Workbook

Sheet README
A1: Supplementary material — anonymized for double-blind review
A2: AI-Induced Technical Debt in Code Generated by Large Language Models: A Systematic Literature Review Oriented to Its Prevention and Measurement
A3: Complete protocol and decision record of the systematic literature review (PRISMA 2020; Kitchenham and Charters). Author information is withheld for review.
A5: Sheets
A6: S0_PRISMA — selection flow of both search arms (main B1–B10; directed complementary B11–B13).
A7: S1_Search_strings — full Boolean text, topic, date, and per-database counts of B1–B13. In Scopus each string was wrapped in TITLE-ABS-KEY(...); in IEEE Xplore it was applied to title, abstract, and index terms. Scopus returned no export for B3 (empty cell); B13 returned no IEEE Xplore records (0).
A8: S2_Criteria — inclusion criteria I1–I14, exclusion criterion E1, and reason codes.
A9: S3_Extraction — the 36 included studies with all eighteen extraction fields. Complementary-arm studies (C01–C04) were coded with an abbreviated form; uncoded cells are empty.
A10: S4a_Screening_main / S4b_Screening_compl — decision log of every record screened (141 main, 15 complementary): title/abstract (TA) and full-text (FT) decisions, reason code, and rationale. Duplicates removed by the screening tool are not exported and not listed.
A11: S5_Quality — QA1–QA6 scores (0 / 0.5 / 1), total, and band of the 36 included studies.
A13: Reason codes
A14: E1a unrelated software-engineering topic · E1b functional performance/benchmark only · E1c unrelated application domain · E1d overview/position/preliminary work without debt evidence · FT-NR full text not retrievable · FT-E no focus on AI technical debt or code quality at full text · INC included. Title/abstract decisions were recorded without a reason; codes E1a–E1d were assigned afterwards from the reviewer's notes.
... A19: Abstracts and raw reviewer notes from the screening tool are not redistributed.

Sheet S0_PRISMA
A1: arm | B1: stage | C1: n
A2: main | B2: identified | C2: 437
A3: main | B3: duplicates | C3: 296
A4: main | B4: screened | C4: 141
A5: main | B5: ta_excluded | C5: 96
A6: main | B6: ta_included | C6: 29
A7: main | B7: ta_maybe | C7: 16
A8: main | B8: sought | C8: 45
A9: main | B9: not_retrieved | C9: 4
A10: main | B10: assessed | C10: 41
A11: main | B11: ft_excluded | C11: 9
A12: main | B12: included | C12: 32
A13: complementary | B13: identified | C13: 35
... A23: complementary | B23: included | C23: 4
A24: total | B24: included | C24: =SUMIFS(C2:C23,B2:B23,"included")

Sheet S1_Search_strings
A1: id | B1: arm | C1: label | D1: topic | E1: sq | F1: type | G1: purpose | H1: executed_on | I1: query | J1: scopus_n | K1: ieee_n | L1: total_n
A2: B1 | B2: main | C2: Broad anchor (AI-TD) | D2: T1 AI-TD characterization | E2: SQ1 | F2: Broad | G2: Identify studies that characterize quality problems in AI-generated code. | H2: 2026-06-04 | I2: ("LLM" OR "large language model" OR "LLM code generation" OR "AI code generation" OR "generative AI" OR "AI-generated code" OR "AI-assisted development" OR "GenAI software") AND ("technical debt" OR "AI technical debt" OR "SATD" OR "self-admitted technical debt" OR "AI-induced technical debt" OR "code quality" OR "code smells" OR "software quality" OR "code debt") | J2: 116 | K2: 35 | L2: =SUM(J2:K2)
A3: B2 | B3: main | C3: Taxonomy / classification | D3: T1 AI-TD characterization | E3: SQ1 | F3: Specific | G3: Find classifications and taxonomies of technical debt specific to AI/LLM systems. | H3: 2026-06-04 | I3: ("LLM" OR "large language model" OR "LLM code generation" OR "AI code generation" OR "generative AI" OR "AI-generated code" OR "AI-assisted development" OR "GenAI software") AND ("technical debt" OR "AI technical debt" OR "SATD" OR "self-admitted technical debt" OR "AI-induced technical debt" OR "code quality" OR "code smells" OR "software quality" OR "code debt") AND ("classification" OR "taxonomy" OR "identification" OR "detection") | J3: 36 | K3: 14 | L3: =SUM(J3:K3)
A4: B3 | B4: main | C4: Spec-driven / SDD | D4: T2 Spec-driven development | E4: SQ2 | F4: By solution | G4: Find intervention proposals based on specification prior to code generation. | H4: 2026-06-04 | I4: ("LLM" OR "large language model" OR "LLM code generation" OR "AI code generation" OR "generative AI" OR "AI-generated code" OR "AI-assisted development" OR "GenAI software") AND ("technical debt" OR "AI technical debt" OR "SATD" OR "self-admitted technical debt" OR "AI-induced technical debt" OR "code quality" OR "code smells" OR "software quality" OR "code debt") AND ("spec-driven" OR "spec-driven development" OR "SDD" OR "SDD protocol" OR "specification-first" OR "structured requirements" OR "requirements-driven" OR "requirements-driven development" OR "spec-first" OR "spec-first coding" OR "harness engineering") | K4: 2 | L4: =SUM(J4:K4)
A5: B4 | B5: main | C5: Specification → quality | D5: T2 Spec-driven development | E5: SQ2 | F5: By solution + outcome | G5: Identify evidence of the effect of the specification on the quality of generated code. | H5: 2026-06-04 | I5: ("LLM" OR "large language model" OR "LLM code generation" OR "AI code generation" OR "generative AI" OR "AI-generated code" OR "AI-assisted development" OR "GenAI software") AND ("technical debt" OR "AI technical debt" OR "SATD" OR "self-admitted technical debt" OR "AI-induced technical debt" OR "code quality" OR "code smells" OR "software quality" OR "code debt") AND ("specification" OR "structured specification" OR "specification document" OR "specification template" OR "pre-specification" OR "structured requirements" OR "structured prompting" OR "requirements quality" OR "requirements document" OR "requirements document LLM") | J5: 8 | K5: 4 | L5: =SUM(J5:K5)
A6: B5 | B6: main | C6: Mitigation strategies | D6: T3 Mitigation strategies | E6: SQ3 | F6: Comparative | G6: Find studies that compare quality-improvement strategies for LLM code. | H6: 2026-06-04 | I6: ("LLM" OR "large language model" OR "LLM code generation" OR "AI code generation" OR "generative AI" OR "AI-generated code" OR "AI-assisted development" OR "GenAI software") AND ("technical debt" OR "AI technical debt" OR "SATD" OR "self-admitted technical debt" OR "AI-induced technical debt" OR "code quality" OR "code smells" OR "software quality" OR "code debt") AND ("prompt engineering" OR "code review" OR "static analysis" OR "refactoring" OR "code inspection" OR "automated testing" OR "quality assurance" OR "code quality improvement" OR "mitigation strategy" OR "prompt optimization" OR "chain-of-thought prompting" OR "zero-shot" OR "few-shot" OR "in-context learning" OR "LLM prompting strategies") | J6: 47 | K6: 26 | L6: =SUM(J6:K6)
A7: B6 | B7: main | C7: Experimental effectiveness | D7: T3 Mitigation strategies | E7: SQ3 | F7: Comparative by outcome | G7: Identify experimental evidence on the effectiveness of interventions on LLM code quality. | H7: 2026-06-04 | I7: ("LLM" OR "large language model" OR "LLM code generation" OR "AI code generation" OR "generative AI" OR "AI-generated code" OR "AI-assisted development" OR "GenAI software") AND ("technical debt" OR "AI technical debt" OR "SATD" OR "self-admitted technical debt" OR "AI-induced technical debt" OR "code quality" OR "code smells" OR "software quality" OR "code debt") AND ("experiment" OR "empirical study" OR "controlled study" OR "evaluation") | J7: 78 | K7: 15 | L7: =SUM(J7:K7)
A8: B7 | B8: main | C8: TD measurement instruments | D8: T4 TD metrics | E8: SQ4 | F8: By outcome | G8: Identify studies that use TD measurement instruments in AI-assisted coding. | H8: 2026-06-04 | I8: ("LLM" OR "large language model" OR "LLM code generation" OR "AI code generation" OR "generative AI" OR "AI-generated code" OR "AI-assisted development" OR "GenAI software") AND ("technical debt" OR "AI technical debt" OR "SATD" OR "self-admitted technical debt" OR "AI-induced technical debt" OR "code quality" OR "code smells" OR "software quality" OR "code debt") AND ("SonarQube" OR "coupling" OR "coupling metrics" OR "coupling analysis" OR "cohesion metrics" OR "afferent coupling" OR "efferent coupling" OR "instability index" OR "debt ratio" OR "SQALE" OR "SATD measurement" OR "technical debt measurement" OR "Sculley checklist") | J8: 3 | K8: 1 | L8: =SUM(J8:K8)
A9: B8 | B9: main | C9: IS success + TD | D9: T4 IS success | E9: SQ4 | F9: Comparative | G9: Find studies that connect technical software quality with IS success. | H9: 2026-06-04 | I9: ("LLM" OR "large language model" OR "LLM code generation" OR "AI code generation" OR "generative AI" OR "AI-generated code" OR "AI-assisted development" OR "GenAI software") AND ("technical debt" OR "AI technical debt" OR "SATD" OR "self-admitted technical debt" OR "AI-induced technical debt" OR "code quality" OR "code smells" OR "software quality" OR "code debt") AND ("information systems success" OR "DeLone McLean" OR "IS success" OR "DeLone McLean IS success" OR "system quality" OR "information quality" OR "net benefits" OR "IS success model" OR "PLS-SEM IS evaluation" OR "information systems measurement") | J9: 1 | K9: 24 | L9: =SUM(J9:K9)
A10: B9 | B10: main | C10: HEI context | D10: T5 HEI context | E10: SQ5 | F10: Broad | G10: Map the presence of the AI-TD problem in the specific context of HEIs. | H10: 2026-06-04 | I10: ("LLM" OR "large language model" OR "LLM code generation" OR "AI code generation" OR "generative AI" OR "AI-generated code" OR "AI-assisted development" OR "GenAI software") AND ("technical debt" OR "AI technical debt" OR "SATD" OR "self-admitted technical debt" OR "AI-induced technical debt" OR "code quality" OR "code smells" OR "software quality" OR "code debt") AND ("higher education" OR "higher education institution" OR "HEI" OR "university" OR "academic institution") AND ("software development" OR "information systems" OR "university information systems" OR "legacy systems" OR "digital transformation" OR "academic software modernization" OR "software modernization HEI") | J10: 2 | K10: 23 | L10: =SUM(J10:K10)
A11: B10 | B11: main | C11: Latin America / gaps | D11: T5 Latin America / gaps | E11: SQ5 | F11: Gap-oriented | G11: Identify the empirical gap in Latin American contexts. | H11: 2026-06-04 | I11: ("LLM" OR "large language model" OR "LLM code generation" OR "AI code generation" OR "generative AI" OR "AI-generated code" OR "AI-assisted development" OR "GenAI software") AND ("technical debt" OR "AI technical debt" OR "SATD" OR "self-admitted technical debt" OR "AI-induced technical debt" OR "code quality" OR "code smells" OR "software quality" OR "code debt") AND ("higher education" OR "higher education institution" OR "HEI" OR "university" OR "academic institution") AND ("Latin America" OR "developing countr*" OR "Ecuador" OR "research gap*") | J11: 1 | K11: 1 | L11: =SUM(J11:K11)
A12: B11 | B12: complementary | C12: Design-by-contract / formal requirements | D12: Formal requirements / design-by-contract / MDD | E12: SQ2 | F12: Directed complementary | G12: Retrieve formal or structured specification disciplines applied before generation (including EARS notation). | H12: 2026-08-13 | I12: ("LLM" OR "large language model" OR "LLM code generation" OR "AI code generation" OR "generative AI" OR "AI-generated code" OR "AI-assisted development" OR "GenAI software") AND ("technical debt" OR "AI technical debt" OR "SATD" OR "self-admitted technical debt" OR "AI-induced technical debt" OR "code quality" OR "code smells" OR "software quality" OR "code debt" OR "code generation") AND ("design by contract" OR "formal specification" OR "model-driven development" OR "requirements engineering" OR "EARS" OR "Easy Approach to Requirements Syntax") | J12: 16 | K12: 4 | L12: =SUM(J12:K12)
A13: B12 | B13: complementary | C13: Contract- and test-first disciplines | D13: Test/contract-first disciplines | E13: SQ2 | F13: Directed complementary | G13: Retrieve test- and contract-first disciplines applied before generation as a preventive mechanism. | H13: 2026-08-13 | I13: ("LLM" OR "large language model" OR "LLM code generation" OR "AI code generation" OR "generative AI" OR "AI-generated code" OR "AI-assisted development" OR "GenAI software") AND ("technical debt" OR "AI technical debt" OR "SATD" OR "self-admitted technical debt" OR "AI-induced technical debt" OR "code quality" OR "code smells" OR "software quality" OR "code debt" OR "specification") AND ("test-driven development" OR "TDD" OR "behavior-driven" OR "BDD" OR "property-based testing" OR "API-first" OR "contract-first" OR "test-first" OR "specification by example" OR "executable specification" OR "acceptance test" OR "consumer-driven contract") | J13: 6 | K13: 2 | L13: =SUM(J13:K13)
A14: B13 | B14: complementary | C14: Structured-input governance | D14: Input structuring / guardrails / policy-as-code | E14: SQ2 | F14: Directed complementary | G14: Retrieve input-structuring and preventive governance approaches (guardrails, policy-as-code). | H14: 2026-08-13 | I14: ("LLM" OR "large language model" OR "LLM code generation" OR "AI code generation" OR "generative AI" OR "AI-generated code" OR "AI-assisted development" OR "GenAI software") AND ("technical debt" OR "AI technical debt" OR "SATD" OR "self-admitted technical debt" OR "AI-induced technical debt" OR "code quality" OR "code smells" OR "software quality" OR "code debt") AND ("task decomposition" OR "scaffolding" OR "guardrails" OR "policy-as-code" OR "structured prompt" OR "spec-driven development" OR "prompt orchestration") | J14: 7 | K14: 0 | L14: =SUM(J14:K14)

Sheet S2_Criteria
A1: code | B1: type | C1: linked_string | D1: linked_sq | E1: criterion
A2: I1 | B2: Thematic inclusion | C2: B1 | D2: SQ1 | E2: Identify studies that characterize quality problems in AI-generated code.
A3: I2 | B3: Thematic inclusion | C3: B2 | D3: SQ1 | E3: Find classifications and taxonomies of specific technical debt for AI/LLM systems.
A4: I3 | B4: Thematic inclusion | C4: B3 | D4: SQ2 | E4: Find intervention proposals based on specification prior to code generation.
A5: I4 | B5: Thematic inclusion | C5: B4 | D5: SQ2 | E5: Identify evidence of the effect of the specification on the quality of the generated code.
A6: I5 | B6: Thematic inclusion | C6: B5 | D6: SQ3 | E6: Find studies that compare quality improvement strategies in LLM code.
A7: I6 | B7: Thematic inclusion | C7: B6 | D7: SQ3 | E7: Identify experimental evidence on the effectiveness of interventions in LLM code quality.
A8: I7 | B8: Thematic inclusion | C8: B7 | D8: SQ4 | E8: Identify studies that use TD measurement instruments in AI-assisted coding.
A9: I8 | B9: Thematic inclusion | C9: B8 | D9: SQ4 | E9: Find studies that connect technical software quality with IS success.
A10: I9 | B10: Thematic inclusion | C10: B9 | D10: SQ5 | E10: Map the presence of the AI-TD problem in the specific context of HEIs.
A11: I10 | B11: Thematic inclusion | C11: B10 | D11: SQ5 | E11: Identify the empirical gap in Latin American contexts.
A12: I11 | B12: Formal inclusion | E12: Publication year 2022-2026.
A13: I12 | B13: Formal inclusion | E13: Document type: Article, Early Access article, or Journal.
A14: I13 | B14: Formal inclusion | E14: Language: English.
A15: I14 | B15: Formal inclusion | E15: Full text available (open access or subscribed content).
A16: E1 | B16: Exclusion | E16: Failure to meet the inclusion criteria; in particular, not related to any of the five topics associated with the review subquestions (SQ1-SQ5).
A17: E1a | B17: Exclusion reason code (title/abstract) | E17: Unrelated software-engineering topic: none of the five review topics is addressed (e.g., test automation, requirements engineering that produces no code, NLP over software artifacts).
A18: E1b | B18: Exclusion reason code (title/abstract) | E18: Functional performance or benchmark only (e.g., pass@k, accuracy, runtime) without addressing technical debt, specification, or IS success.
A19: E1c | B19: Exclusion reason code (title/abstract) | E19: Unrelated application domain without transferability to institutional IS (e.g., hardware/HDL, blockchain, IoT, robotics, infrastructure-as-code, safety-critical, security not tied to maintainability).
A20: E1d | B20: Exclusion reason code (title/abstract) | E20: Overview, position, roadmap, or preliminary work without technical-debt or code-quality evidence.
A21: FT-NR | B21: Exclusion reason code (full text) | E21: Full text not retrievable (reports not retrieved).
A22: FT-E | B22: Exclusion reason code (full text) | E22: No focus on AI technical debt or code quality on full-text reading.
A23: INC | B23: Decision code | E23: Included in the synthesis.
A24: QA | B24: Quality appraisal (not gating) | E24: Eligibility is decided solely by the criteria above. Each included study is scored with a six-criterion rubric (QA1-QA6; 0/0.5/1). Journal quartile or venue prestige is not used as a proxy for quality.

Sheet S3_Extraction
A1: id | B1: bibtex_key | C1: arm | D1: first_author | E1: year | F1: title | G1: document_type | H1: venue | I1: doi | J1: source_database | K1: search_string | L1: objective | M1: problem | N1: context | O1: intervention_method | P1: comparison | Q1: study_type | R1: sample_dataset | S1: tools | T1: metrics | U1: main_results | V1: limitations | W1: gap | X1: relation_to_review | Y1: sq | Z1: method_short | AA1: key_finding | AB1: qa_total | AC1: qa_band
A2: A002 | B2: A002_Patel2026 | C2: main | D2: Patel et al. | E2: 2026 | F2: Code Comprehension Gaps in AI-Assisted Development: A Conceptual Framework for Knowledge Erosion Patterns | G2: Journal article | H2: IEEE Access | I2: 10.1109/access.2026.3689574 | J2: IEEE Xplore | K2: B1 | L2: Build a conceptual framework of knowledge erosion and comprehension gaps in AI-assisted development. | M2: Codebases fill with AI-generated code that developers do not understand, document, or maintain as they do human code. | N2: Organizational software engineering; references ISO/IEC 25010 and GDPR Art. 22. | O2: Taxonomy of five knowledge voids (provenance, edge case, integration, evolution, security), a five-level comprehension scale, and a conceptual model of debt accumulation. | P2: AI-generated vs. human-written code (conceptual). | Q2: Theoretical/conceptual (hypothesis-generating, not validated). | R2: None (no measured data). | S2: None; discusses Copilot, CodeWhisperer, ChatGPT. | T2: None; an illustrative, unmeasured debt-accumulation model. | U2: AI introduces a qualitatively different genesis of debt: debt can exist from creation because understanding was never acquired, and the usual recovery mechanism (asking the author) is missing. | V2: Purely conceptual, no empirical evidence (stated by the authors); illustrative figures. | W2: Longitudinal validation of knowledge erosion; objective measurement of comprehension in production. | X2: SQ1 framing: conceptual account of how AI-TD originates (provenance void). Used as a framework, not as evidence. | Y2: SQ1 | Z2: Conceptual framework | AA2: Knowledge-erosion patterns; provenance void | AB2: =INDEX(S5_Quality!$I$2:$I$37,MATCH(A2,S5_Quality!$A$2:$A$37,0)) | AC2: =INDEX(S5_Quality!$J$2:$J$37,MATCH(A2,S5_Quality!$A$2:$A$37,0))
A3: A003 | B3: A003_Meske2025 | C3: main | D3: Meske et al. | E3: 2025 | F3: Vibe Coding as a Reconfiguration of Intent Mediation in Software Development: Definition, Implications, and Research Agenda | G3: Journal article | H3: IEEE Access | I3: 10.1109/access.2025.3645466 | J3: IEEE Xplore | K3: B1 | L3: Define and conceptualize vibe coding as a development paradigm and analyse its implications. | M3: Gap between rapid adoption of vibe coding and its conceptual understanding; quality risks. | N3: Information systems / HCI; general software development. | O3: Conceptualization through a historical analysis of intent mediation, plus a research agenda. | P3: Deterministic instruction vs. probabilistic inference. | Q3: Theoretical/conceptual (perspective, no primary data). | R3: None; cites third-party statistics. | S3: Generative AI / LLMs as a category. | T3: None. | U3: Vibe coding shifts intent mediation from deterministic instruction to probabilistic inference; central risks are black-box codebases, responsibility gaps, deskilling, accelerated technical debt, and loss of traceability of intent. | V3: Purely conceptual; relies on third-party evidence; IS/HCI perspective. | W3: Human, technical, and organizational agenda; lack of traceability and governance mechanisms. | X3: SQ1 (conceptual): names the paradigm in which intent erodes and debt accumulates incrementally. | Y3: SQ1 | Z3: Conceptual (HCI) | AA3: Vibe-coding intent erosion; incremental debt | AB3: =INDEX(S5_Quality!$I$2:$I$37,MATCH(A3,S5_Quality!$A$2:$A$37,0)) | AC3: =INDEX(S5_Quality!$J$2:$J$37,MATCH(A3,S5_Quality!$A$2:$A$37,0))
A4: A007 | B4: A007_Dubey2026 | C4: main | D4: Dubey & Madisetti | E4: 2026 | F4: eXAI-CodeDebug: Towards Reliable, Trustworthy, and Explainable LLM-Based Coding for Production Systems | G4: Journal article | H4: Computing in Science & Engineering | I4: 10.1109/mcse.2026.3684488 | J4: IEEE Xplore | K4: B1 | L4: Design an explainable framework combining static analysis and an LLM for production code. | M4: AI tools lack transparency, confidence scores, and explanations; static analysers miss AI-specific issues. | N4: Production code; general. | O4: eXAI-CodeDebug: hybrid detection (Pylint + Bandit + GPT-4) with dual confidence scores, explanations, and automatic correction across seven issue categories. | P4: Against black-box IDE/LLM tools. | Q4: Framework proposal with prototype evaluation. | R4: 48 seeded issues. | S4: Pylint, Bandit, GPT-4. | T4: Precision/recall per category, F1, quick-fix success, time. | U4: 100% precision/recall for security and hallucination issues, 85.7% F1 for bug/quality/trustworthiness, 69% quick-fix success; debugging time reduced from 6-23 min to under 2 s per issue; static tools miss AI-specific issues such as hallucinations. | V4: Small evaluation (48 issues); prototype; reactive detection; Python only. | W4: Validation on real systems at scale. | X4: SQ3: hybrid static analysis + LLM as a reactive mitigation strategy; also characterizes AI-specific defects (SQ1). | Y4: SQ3 | Z4: Empirical, LLM + static analysis | AA4: eXAI-CodeDebug: 7 issue categories; high prec/recall (n = 48) | AB4: =INDEX(S5_Quality!$I$2:$I$37,MATCH(A4,S5_Quality!$A$2:$A$37,0)) | AC4: =INDEX(S5_Quality!$J$2:$J$37,MATCH(A4,S5_Quality!$A$2:$A$37,0))
A5: A008 | B5: A008_Alabdullatif2026 | C5: main | D5: Alabdullatif | E5: 2026 | F5: Security and Reliability of AI-Generated C++ Code: A Static Analysis Study Aligned With Saudi NCA Essential Cybersecurity Controls (ECC) | G5: Journal article | H5: IEEE Access | I5: 10.1109/access.2026.3679355 | J5: IEEE Xplore | K5: B1 | L5: Assess the security and reliability of AI-generated C++ code and the effect of prompt-based repair. | M5: LLM-generated C++ may contain vulnerabilities, a concern in safety-critical and regulated domains. | N5: Safety-critical/regulated C++ (automotive, aerospace, health); Saudi Arabia. | O5: Three phases: baseline analysis, prompt-based repair, re-analysis; mapping to CWE and the national Essential Cybersecurity Controls. | P5: Four LLMs; before vs. after repair. | Q5: Experimental (before/after). | R5: C++ programs across application domains, repeated generations. | S5: ChatGPT, Claude, DeepSeek, Gemini; Cppcheck, Clang-Tidy; CWE. | T5: Static-analysis findings by type; mapped CWEs; before/after counts. | U5: Recurring weaknesses (e.g., CWE-457, numeric conversions); prompt-based repair reduces but does not eliminate findings and sometimes increases them (Cppcheck: ChatGPT +129, DeepSeek +182). | V5: Safety-critical C++ limits transferability; CWE-control mapping involves judgement; security focus. | W5: Adaptive prompting; model-specific repair techniques. | X5: SQ3: reactive prompt-based repair is insufficient and can be counter-productive; also characterizes security debt (SQ1). | Y5: SQ3 | Z5: Static analysis (C++, CWE) | AA5: Prompt repair reduces but can worsen findings | AB5: =INDEX(S5_Quality!$I$2:$I$37,MATCH(A5,S5_Quality!$A$2:$A$37,0)) | AC5: =INDEX(S5_Quality!$J$2:$J$37,MATCH(A5,S5_Quality!$A$2:$A$37,0))
A6: A010 | B6: A010_Krebs2025 | C6: main | D6: Krebs & Mazumdar | E6: 2025 | F6: Analyzing LLM-Generated Code According to Four ISO/IEC 5055:2021 Categories | G6: Journal article | H6: IEEE Access | I6: 10.1109/access.2025.3637569 | J6: IEEE Xplore | K6: B1 | L6: Measure how far LLM-generated code meets the four ISO/IEC 5055 quality categories. | M6: No comprehensive assessment of LLM code across maintainability, reliability, performance efficiency, and security. | N6: Multi-domain tasks (HPC, ML, data processing). | O6: Evaluation with stratified prompting (short/medium/long) and a weighted composite score per ISO/IEC 5055 category. | P6: Nine LLMs against each other and against a human-developer baseline. | Q6: Quantitative experimental study. | R6: 9 algorithms × 3 domains; 9 LLMs; 3 prompt levels. | S6: Pylint, Radon (CC, MI, Halstead), Bandit, psutil; GPT-4-Turbo, Gemini, DeepSeek-Coder and others. | T6: Maintainability Index, cyclomatic complexity, Halstead delivered bugs, SLOC, CPU/memory; composite scores. | U6: GPT-4-Turbo best on reliability, efficiency, and security; Gemini best on maintainability, yet no LLM exceeded the human baseline on the maintainability composite (Gemini −12%); prompting alone does not ensure consistent quality. | V6: Model opacity prevents causal interpretation; modest sample of nine algorithms; temporal limitation. | W6: Extension to other languages and real systems; integrated validation. | X6: SQ1 (quality profile of LLM code) and SQ4 (composite quality score as a measurement precedent). | Y6: SQ1, SQ4 | Z6: Static analysis, ISO/IEC 5055 | AA6: Matches human per category; below human maintainability composite | AB6: =INDEX(S5_Quality!$I$2:$I$37,MATCH(A6,S5_Quality!$A$2:$A$37,0)) | AC6: =INDEX(S5_Quality!$J$2:$J$37,MATCH(A6,S5_Quality!$A$2:$A$37,0))
A7: A013 | B7: A013_Khojah2025 | C7: main | D7: Khojah et al. | E7: 2025 | F7: The Impact of Prompt Programming on Function-Level Code Generation | G7: Journal article | H7: IEEE Transactions on Software Engineering | I7: 10.1109/tse.2025.3587794 | J7: IEEE Xplore | K7: B1 | L7: Determine how prompting techniques and their combinations affect correctness, similarity, and quality of generated code. | M7: The impact of interacting prompting techniques on function-level generation is not well studied. | N7: Function-level code generation. | O7: Full factorial experiment of five techniques and their 32 combinations (CodePromptEval). | P7: Few-shot, persona, chain-of-thought, function signature, list of packages, and combinations; three LLMs. | Q7: Experimental (full factorial). | R7: CodePromptEval: 7,072 prompts (221 CoderEval tasks × 32). | S7: GPT-4o, Llama 3, Mistral; Pylint; complexity analysis. | T7: Correctness (tests), CrystalBLEU, code smells (Pylint), cyclomatic and cognitive complexity; Wilcoxon, Vargha-Delaney A12. | U7: Combining techniques does not necessarily help; there is a correctness-maintainability trade-off; interface information (signature, few-shot) has the clearest effect; a strong emphasis on prompt programming is not necessary. | V7: Function level only; docstring-based tasks; sensitivity to prompt format. | W7: Datasets more representative of real projects. | X7: SQ3: the most rigorous evidence on the limited added value of prompt engineering for code quality. | Y7: SQ3 | Z7: Controlled exp. (7,072 prompts) | AA7: Prompt engineering: limited added gain; correctness-quality trade-off | AB7: =INDEX(S5_Quality!$I$2:$I$37,MATCH(A7,S5_Quality!$A$2:$A$37,0)) | AC7: =INDEX(S5_Quality!$J$2:$J$37,MATCH(A7,S5_Quality!$A$2:$A$37,0))
A8: A014 | B8: A014_Haindl2024 | C8: main | D8: Haindl & Weinberger | E8: 2024 | F8: Does ChatGPT Help Novice Programmers Write Better Code? Results From Static Code Analysis | G8: Journal article | H8: IEEE Access | I8: 10.1109/access.2024.3445432 | J8: IEEE Xplore | K8: B1 | L8: Determine whether ChatGPT improves the code quality of novice programmers. | M8: Uncertain impact of ChatGPT on code quality in education. | N8: Higher education: introductory Java course, novice students. | O8: Controlled experiment (ChatGPT-assisted vs. unassisted). | P8: Control group (16) vs. treatment group (22). | Q8: Controlled experiment. | R8: 38 students; identical exercises on coding conventions. | S8: ChatGPT; Checkstyle, PMD. | T8: Rule violations, cyclomatic complexity, cognitive complexity. | U8: The ChatGPT group improved code quality significantly (fewer violations, lower cyclomatic/cognitive complexity), but adapting the generated code required high effort and submissions were a mix of student and ChatGPT code. | V8: Small sample (38); novices; simple exercises; single course. | W8: Replication with larger, more diverse populations and other educational settings. | X8: SQ5: HEI evidence on LLM-assisted code quality; also compares assisted vs. unassisted work (SQ3) with static metrics (SQ4). | Y8: SQ5 | Z8: Controlled exp. (university) | AA8: ChatGPT effect on novice code quality (small n) | AB8: =INDEX(S5_Quality!$I$2:$I$37,MATCH(A8,S5_Quality!$A$2:$A$37,0)) | AC8: =INDEX(S5_Quality!$J$2:$J$37,MATCH(A8,S5_Quality!$A$2:$A$37,0))
A9: A027 | B9: A027_Zhuo2026 | C9: main | D9: Zhuo et al. | E9: 2026 | F9: Getting Acquainted with Your LLMs: Are They Aware of Smelly Code? | G9: Journal article (theme article) | H9: IEEE Software | I9: 10.1109/ms.2026.3665838 | J9: IEEE Xplore | K9: B1 | L9: Determine whether LLMs perceive code quality (code smells) in addition to functionality. | M9: LLM fluency may mask insensitivity to technical debt. | N9: Open-source Java code (brownfield); code-explanation task. | O9: Data-driven black-box behavioral probe using code smells as probes; audience-centric prompting with three personas. | P9: Smelly vs. clean code; persona vs. persona; model vs. model. | Q9: Exploratory empirical study. | R9: 4,358 Java methods from CodeXGLUE; 10 smell types in 4 categories. | S9: GPT-4o, GLM-4; DeepSeek-V3.2 as judge; sentence embeddings; BLEU/ROUGE/METEOR. | T9: Kolmogorov-Smirnov tests, medoid distance, LLM-as-judge quality awareness and role sensitivity, verbatim recycling. | U9: Widespread insensitivity to smells (p > 0.05); a Yes-Man behavior that rationalizes defective code; quality awareness absent in 55% of explanations; low role sensitivity in over 80%. | V9: Java/CodeXGLUE only; heuristic smell labels; two models; LLM-judge bias (mitigated); exploratory. | W9: Need for explicit structure and constraints rather than relying on LLM self-detection. | X9: SQ1: LLMs do not reliably recognize the debt they produce; also bounds LLM-based review (SQ3). | Y9: SQ1 | Z9: Empirical | AA9: LLMs insensitive to code smells ('Yes-Man') | AB9: =INDEX(S5_Quality!$I$2:$I$37,MATCH(A9,S5_Quality!$A$2:$A$37,0)) | AC9: =INDEX(S5_Quality!$J$2:$J$37,MATCH(A9,S5_Quality!$A$2:$A$37,0))
A10: A037 | B10: A037_Alomar2025 | C10: main | D10: Alomar | E10: 2025 | F10: Nurturing Code Quality: Leveraging Static Analysis and Large Language Models for Software Quality in Education | G10: Journal article | H10: ACM Transactions on Computing Education | I10: 10.1145/3722229 | J10: Scopus | K10: B1 | L10: Examine how PMD and ChatGPT support code-quality improvement in the classroom. | M10: Linter warnings are often non-actionable; the role of ChatGPT in educational code review is unclear. | N10: Higher education: undergraduate/graduate code-review activity. | O10: Integration of PMD (static analysis) and ChatGPT (helper) in code review. | P10: Added value of ChatGPT over PMD. | Q10: Empirical, quantitative and qualitative (educational experience). | R10: 155 submissions; 1,658 PMD rule findings. | S10: PMD; ChatGPT; expert assessment and student feedback. | T10: Issue categories, resolution time, success ratios (student perception). | U10: For 93% of issues ChatGPT identified nothing beyond PMD; design issues took longest to resolve; prompts addressing clarity, complexity, and context support learning; a PMD + ChatGPT synergy is recommended. | V10: One course and instructor; self-reported perception; no structural TD metrics. | W10: Integrating code review into the curriculum; effective strategies. | X10: SQ3: limit of the LLM as reviewer relative to a linter; HEI setting (SQ5). | Y10: SQ3 | Z10: 155 submissions, PMD vs. ChatGPT | AA10: ChatGPT adds no value over PMD in 93% | AB10: =INDEX(S5_Quality!$I$2:$I$37,MATCH(A10,S5_Quality!$A$2:$A$37,0)) | AC10: =INDEX(S5_Quality!$J$2:$J$37,MATCH(A10,S5_Quality!$A$2:$A$37,0))
A11: A040 | B11: A040_Gnieciak2025 | C11: main | D11: Gnieciak & Szandala | E11: 2025 | F11: Large Language Models Versus Static Code Analysis Tools: A Systematic Benchmark for Vulnerability Detection | G11: Journal article | H11: IEEE Access | I11: 10.1109/access.2025.3635168 | J11: Scopus | K11: B1 | L11: Compare LLMs and static analysis tools head-to-head on vulnerability detection. | M11: Static tools are noisy with limited coverage; the role of LLMs is emerging. | N11: Real C# projects; security. | O11: Open benchmark and evaluation protocol; recommends a hybrid pipeline. | P11: Three LLMs (GPT-4.1, Mistral Large, DeepSeek V3) vs. three static tools (SonarQube, CodeQL, Snyk Code). | Q11: Systematic benchmark (quantitative and qualitative). | R11: 10 C# projects with 63 vulnerabilities. | S11: GitHub Models; SonarQube, CodeQL, Snyk Code. | T11: Precision, recall, F1, latency, vetting effort. | U11: LLMs reach F1 0.75-0.80 vs. 0.26-0.55 for static tools (driven by recall), but mislocalize issues and produce false positives; a hybrid of early LLM triage and static verification is recommended. | V11: Security domain in C#, not maintainability debt; 63 vulnerabilities; static-tool F1 refers to vulnerabilities, not code smells. | W11: Hybrid pipelines; better localization; multi-language coverage. | X11: SQ3: comparison of LLM-based and static-analysis detection; calibrates static tools as instruments (SQ4). | Y11: SQ3 | Z11: Benchmark (10 C# projects) | AA11: LLMs vs. SonarQube/CodeQL; hybrid pipeline advised | AB11: =INDEX(S5_Quality!$I$2:$I$37,MATCH(A11,S5_Quality!$A$2:$A$37,0)) | AC11: =INDEX(S5_Quality!$J$2:$J$37,MATCH(A11,S5_Quality!$A$2:$A$37,0))
A12: A041 | B12: A041_MohammedSalih2025 | C12: main | D12: Mohammed Salih & Sarhan | E12: 2025 | F12: A Study of Large Language Models in Detecting Python Code Violations | G12: Journal article | H12: ARO-The Scientific Journal of Koya University | I12: 10.14500/aro.12395 | J12: Scopus | K12: B1 | L12: Assess LLMs vs. static tools in detecting Python code violations, and the effect of prompting. | M12: Static tools lack deep semantic and contextual understanding. | N12: Python code; quality violations. | O12: Comparison of LLMs and static tools under three prompting strategies. | P12: Six LLMs vs. Pylint and Flake8; structured vs. chain-of-thought vs. role-based prompts. | Q12: Experimental (quantitative and qualitative). | R12: 75 Python snippets with 27 violation types (including PEP 8). | S12: ChatGPT, Gemini, Claude Sonnet, DeepSeek, Kimi, Qwen; Pylint, Flake8. | T12: Precision, recall, F1. | U12: Claude Sonnet reached the best F1 (0.81), above Flake8 (0.79); structured prompts gave the most balanced results, while chain-of-thought and role prompts were irregular; per-snippet processing beat batch processing. | V12: Small sample (75 snippets); lower-impact venue; LLMs struggle with multi-file context. | W12: Generalization to other languages; LLMs as a complement to static tools. | X12: SQ3: compares prompting strategies and static tools; structured input yields more balanced detection. | Y12: SQ3 | Z12: 6 LLMs vs. Pylint/Flake8 | AA12: Structured prompts beat CoT/role for review | AB12: =INDEX(S5_Quality!$I$2:$I$37,MATCH(A12,S5_Quality!$A$2:$A$37,0)) | AC12: =INDEX(S5_Quality!$J$2:$J$37,MATCH(A12,S5_Quality!$A$2:$A$37,0))
A13: A045 | B13: A045_Gheventer2026 | C13: main | D13: Gheventer et al. | E13: 2026 | F13: Generative AI solutions for software quality: Assessing industrial readiness | G13: Journal article | H13: Software Quality Journal | I13: 10.1007/s11219-026-09754-7 | J13: Scopus | K13: B1 | L13: Assess the maturity and industrial readiness of GenAI solutions for software quality. | M13: Gap between research prototypes and production-ready tools. | N13: GenAI solutions for software quality; Brazilian authorship. | O13: Rapid multivocal literature review; classification by ISO/IEC 25010 and SDLC phase. | P13: 24 solutions; academic vs. grey sources. | Q13: Literature review (rapid multivocal). | R13: 24 GenAI solutions (Scopus, Google, GitHub, PapersWithCode). | S13: ISO/IEC 25010 framework; diverse LLM solutions. | T13: Classification by ISO/IEC 25010 attributes and SDLC phase (maturity). | U13: Low maturity; a last-mile problem from prototype to production; a strategic adoption dilemma; scarcity of realistic public data; a reliability gap between academia and industry. | V13: Secondary study; does not measure TD or code; focus on tool maturity. | W13: Contamination-free benchmarks, explainable architectures, guidance for real integration. | X13: SQ5: field maturity and the last-mile gap; Latin American (Brazilian) authorship. | Y13: SQ5 | Z13: Rapid MLR (24 tools) | AA13: Low industrial maturity; last-mile gap | AB13: =INDEX(S5_Quality!$I$2:$I$37,MATCH(A13,S5_Quality!$A$2:$A$37,0)) | AC13: =INDEX(S5_Quality!$J$2:$J$37,MATCH(A13,S5_Quality!$A$2:$A$37,0))
... A33: A131 | B33: A131_MohammedSalih2025survey | C33: main | D33: Mohammed Salih & Sarhan | E33: 2025 | F33: A Systematic Survey on Large Language Models for Static Code Analysis | G33: Journal article (survey) | H33: ARO-The Scientific Journal of Koya University | I33: 10.14500/aro.12082 | J33: Scopus | K33: B1 | L33: Map the state of the art of LLMs for static code analysis (seven research questions). | M33: Few surveys examine LLMs specifically for static analysis. | N33: Static code analysis; global. | O33: Systematic survey with a taxonomy. | P33: Prompting strategies and tools across studies. | Q33: Literature review (systematic survey). | R33: Corpus of papers from major databases. | S33: Overview of ChatGPT and other models; catalog of tools and metrics. | T33: Catalogue of metrics used (cyclomatic and cognitive complexity, code smells, WMC, nesting) and prompting strategies. | U33: Structured prompting is the most used strategy (8 papers); seven challenges (non-determinism, hallucinations, scalability) and eight future directions identified. | V33: Secondary study; lower-impact venue; focus on detection, not generation. | W33: None of the eight future directions includes a preventive specification-driven protocol. | X33: SQ2: confirms structured prompting as dominant and the absence of preventive specification protocols in the research agenda. | Y33: SQ2 | Z33: Systematic survey | AA33: LLMs for static analysis; no SDD prevention in agenda | AB33: =INDEX(S5_Quality!$I$2:$I$37,MATCH(A33,S5_Quality!$A$2:$A$37,0)) | AC33: =INDEX(S5_Quality!$J$2:$J$37,MATCH(A33,S5_Quality!$A$2:$A$37,0))
A34: C01 | B34: C01_Newcomb2025 | C34: complementary | D34: Newcomb et al. | E34: 2025 | F34: Preconditions and Postconditions as Design Constraints for LLM Code Generation | G34: Journal article | H34: IEEE Access | I34: 10.1109/access.2025.3625819 | J34: IEEE Xplore | K34: B11 | O34: Design-by-contract: explicit preconditions and postconditions as structured specification before generation; structured evaluation of six LLMs generating a medium-complexity system from class-level specifications, with vs. without design constraints. | P34: With vs. without design constraints; six LLMs. | Q34: Structured evaluation. | R34: Six LLMs; Python, C++, Java. | T34: pass@k (pass@5, pass@10), compilation success rate, test success rate. | U34: Design constraints significantly increase generation accuracy (especially Python, also C++); smaller models benefit most. | V34: Maintainability and coupling are not measured (design rationale only); risk of dataset leakage. | X34: SQ2: preventive specification before generation, measured on correctness (pass@k) rather than debt. | Y34: SQ2 | Z34: Structured eval. (6 LLMs) | AA34: Design-by-contract raises generation accuracy | AB34: =INDEX(S5_Quality!$I$2:$I$37,MATCH(A34,S5_Quality!$A$2:$A$37,0)) | AC34: =INDEX(S5_Quality!$J$2:$J$37,MATCH(A34,S5_Quality!$A$2:$A$37,0))
A35: C02 | B35: C02_Jin2026 | C35: complementary | D35: Jin & Chen | E35: 2026 | F35: Are LLMs reliable code reviewers? systematic overcorrection in requirement conformance judgement | G35: Journal article | H35: Automated Software Engineering | I35: 10.1007/s10515-026-00638-5 | J35: Scopus | K35: B13 | O35: Empirical evaluation of LLM-as-a-judge for code review and code-requirement conformance (without test cases) on benchmarks under three prompting approaches; proposes a fix-guided verification filter. | P35: Three prompting approaches. | Q35: Empirical evaluation on benchmarks. | R35: HumanEval+, MBPP, and other benchmarks. | T35: Misjudgement rates (false negatives = over-correction; false positives = unsafe acceptance). | U35: LLMs misjudge correct code as defective (over-correction bias); more detailed prompts lead to more errors. | X35: SQ3: limits of LLM-based code review as a mitigation strategy; failure mode (SQ1). | Y35: SQ3 | Z35: Benchmarks (HumanEval/MBPP) | AA35: LLM-reviewer over-correction; Fix-guided filter | AB35: =INDEX(S5_Quality!$I$2:$I$37,MATCH(A35,S5_Quality!$A$2:$A$37,0)) | AC35: =INDEX(S5_Quality!$J$2:$J$37,MATCH(A35,S5_Quality!$A$2:$A$37,0))
A36: C03 | B36: C03_Expecto2026 | C36: complementary | D36: Lee & Heo | E36: 2026 | F36: Expecto: Extracting Formal Specifications from Natural Language Description for Trustworthy Oracles | G36: Journal article (PACMPL) | H36: Proceedings of the ACM on Programming Languages | I36: 10.1145/3808332 | J36: Scopus | K36: B11 | O36: Neuro-symbolic approach (LLM + program synthesis) that extracts trustworthy formal specifications in a DSL from natural-language intent, within specification-driven development; top-down, modular synthesis. | P36: Against a monolithic-LLM baseline. | Q36: Empirical evaluation (neuro-symbolic technique). | R36: HumanEval+, APPS, Defects4J. | T36: Accuracy and robustness of extracted specifications; bugs detected using specifications as oracles. | U36: Extracts 3.0-7.0× more correct bug-detecting specifications than the baseline; outperforms the monolithic LLM. | X36: SQ2: specification-driven technique whose object is the extraction and verification of formal specifications, not technical debt. | Y36: SQ2 | Z36: Neuro-symbolic (Defects4J) | AA36: Expecto: SDD formal-spec extraction; more bugs found | AB36: =INDEX(S5_Quality!$I$2:$I$37,MATCH(A36,S5_Quality!$A$2:$A$37,0)) | AC36: =INDEX(S5_Quality!$J$2:$J$37,MATCH(A36,S5_Quality!$A$2:$A$37,0))
A37: C04 | B37: C04_Horvat2026 | C37: complementary | D37: Horvat et al. | E37: 2026 | F37: Comparative Evaluation of Gemini and DeepSeek for LLM-Generated Code Quality and Architectural Robustness in Backend Software Engineering | G37: Journal article | H37: Electronics (Switzerland) | I37: 10.3390/electronics15132805 | J37: Scopus | K37: B13 | O37: Comparative empirical evaluation (Gemini 3 Pro vs. DeepSeek-V3.1) generating a Java/Spring Boot backend via structured prompt chaining (vibe coding). | P37: Gemini 3 Pro vs. DeepSeek-V3.1. | Q37: Comparative empirical evaluation. | R37: Java/Spring Boot backend generated by each model. | T37: Manual corrections, functional correctness, architectural robustness (coupling: DTO vs. raw JPA), maintainability, latency, test quality/coverage, static code quality. | U37: Gemini: decoupled DTO architecture, 90.25% requirements met, 95.7% test success, 55.9% coverage; DeepSeek: raw JPA and tight coupling, 68.08%, 74.1%, 45.6%; both require expert supervision. | X37: SQ1: architectural debt in LLM code; comparison of models (SQ3); multi-dimensional measurement (SQ4). | Y37: SQ1, SQ3, SQ4 | Z37: Empirical (Java/Spring Boot) | AA37: Vibe-coding: coupling & coverage differ across models | AB37: =INDEX(S5_Quality!$I$2:$I$37,MATCH(A37,S5_Quality!$A$2:$A$37,0)) | AC37: =INDEX(S5_Quality!$J$2:$J$37,MATCH(A37,S5_Quality!$A$2:$A$37,0))

Sheet S4a_Screening_main
A1: n | B1: record_id | C1: first_author | D1: year | E1: title | F1: venue | G1: doi | H1: ta_decision | I1: ft_decision | J1: reason_code | K1: rationale
A2: 1 | B2: A023 | C2: Amos et al. | D2: 2025 | E2: A Bibliometric Exposition and Review on Leveraging LLMs for Programming Education | F2: IEEE Access | G2: 10.1109/access.2025.3554627 | H2: Maybe | I2: Exclude | J2: FT-E | K2: Bibliometric review of LLMs in programming education; pedagogical focus with no AI-TD or code-quality evidence.
A3: 2 | B3: A024 | C3: Kwon et al. | D3: 2023 | E3: Exploring LLM-Based Automated Repairing of Ansible Script in Edge-Cloud Infrastructures | F3: Journal of Web Engineering | G3: 10.13052/jwe1540-9589.2263 | H3: Exclude | I3: Not assessed | J3: E1c | K3: LLM-based repair of Ansible scripts in edge-cloud infrastructure-as-code; domain not transferable to institutional IS code.
A4: 3 | B4: A025 | C4: Yu et al. | D4: 2026 | E4: A Framework for Evaluating GenAI Adoption and Use in Software Engineering | F4: IEEE Transactions on Software Engineering | G4: 10.1109/tse.2026.3688745 | H4: Maybe | I4: Exclude | J4: FT-E | K4: Organizational governance framework for GenAI adoption quality (ISO/IEC 25059); process level, no AI-TD in generated code.
A5: 4 | B5: A026 | C5: Almanasra & Suwais | D5: 2025 | E5: Analysis of ChatGPT-Generated Codes Across Multiple Programming Languages | F5: IEEE Access | G5: 10.1109/access.2025.3538050 | H5: Exclude | I5: Not assessed | J5: E1b | K5: ChatGPT-4o on LeetCode problems with runtime and memory metrics; functional performance only.
A6: 5 | C6: Umer | D6: 2025 | E6: Comparative Analysis of the Code Generated by Popular Large Language Models (LLMs) for MISRA C++ Compliance | F6: IEEE Access | G6: 10.1109/access.2025.3633086 | H6: Exclude | I6: Not assessed | J6: E1c | K6: MISRA C++ compliance of LLM code for avionics/safety-critical systems; domain-specific standards not transferable.
A7: 6 | C7: Vito et al. | D7: 2025 | E7: SecLLM: Enhancing Security Smell Detection in IaC With Large Language Models | F7: IEEE Access | G7: 10.1109/access.2025.3637505 | H7: Exclude | I7: Not assessed | J7: E1c | K7: LLMs as detectors of security smells in IaC scripts; inverse direction (LLM as detector) and cloud-infrastructure domain.
A8: 7 | B8: A001 | C8: Palla & Slaby | D8: 2025 | E8: Evaluation of Generative AI Models in Python Code Generation: A Comparative Study | F8: IEEE Access | G8: 10.1109/access.2025.3560244 | H8: Exclude | I8: Not assessed | J8: E1b | K8: Comparative performance of LLMs in Python code generation (syntactic accuracy, cost); no technical-debt measurement.
A9: 8 | B9: A002 | C9: Patel et al. | D9: 2026 | E9: Code Comprehension Gaps in AI-Assisted Development: A Conceptual Framework for Knowledge Erosion Patterns | F9: IEEE Access | G9: 10.1109/access.2026.3689574 | H9: Include | I9: Include | J9: INC | K9: Conceptual taxonomy of knowledge-erosion patterns in AI-assisted code; no empirical validation (framing use).
A10: 9 | B10: A003 | C10: Meske et al. | D10: 2025 | E10: Vibe Coding as a Reconfiguration of Intent Mediation in Software Development: Definition, Implications, and Research Agenda | F10: IEEE Access | G10: 10.1109/access.2025.3645466 | H10: Maybe | I10: Include | J10: INC | K10: Defines vibe coding as a shift in intent mediation and names debt accumulation as a central risk; conceptual.
A11: 10 | B11: A004 | C11: Wang et al. | D11: 2026 | E11: SimBench: A Framework for Evaluating and Diagnosing LLM-Based Digital-Twin Generation for Multi-Physics Simulation | F11: IEEE Access | G11: 10.1109/access.2026.3685519 | H11: Exclude | I11: Not assessed | J11: E1c | K11: Benchmark of LLMs generating digital twins for physics simulators; unrelated domain and metrics.
A12: 11 | B12: A005 | C12: Ma et al. | D12: 2025 | E12: A Dual-Stage Framework for Behavior-Enhanced Automated Code Generation in Industrial-Scale Meta-Models | F12: IEEE Access | G12: 10.1109/access.2025.3614174 | H12: Exclude | I12: Not assessed | J12: E1c | K12: Code generation from industrial meta-models (AUTOSAR, OPC UA); automotive model-driven domain.
A13: 12 | B13: A006 | C13: Otoum & Elkhalili | D13: 2026 | E13: Methods and Techniques of Agentic Software Engineering: A Systematic Literature Review | F13: IEEE Access | G13: 10.1109/access.2026.3652325 | H13: Exclude | I13: Not assessed | J13: E1a | K13: SLR on agentic software-engineering architectures; does not address AI-TD, specification, or IS success.
A14: 13 | B14: A007 | C14: Dubey & Madisetti | D14: 2026 | E14: eXAI-CodeDebug: Towards Reliable, Trustworthy, and Explainable LLM-Based Coding for Production Systems | F14: Computing in Science & Engineering | G14: 10.1109/mcse.2026.3684488 | H14: Include | I14: Include | J14: INC | K14: Hybrid static analysis + LLM framework detecting and fixing defects in AI-generated code (seven issue categories).
A15: 14 | B15: A008 | C15: Alabdullatif | D15: 2026 | E15: Security and Reliability of AI-Generated C++ Code: A Static Analysis Study Aligned With Saudi NCA Essential Cybersecurity Controls (ECC) | F15: IEEE Access | G15: 10.1109/access.2026.3679355 | H15: Include | I15: Include | J15: INC | K15: Static analysis (Cppcheck, Clang-Tidy, CWE) of AI-generated C++ code before and after prompt-based repair.
A16: 15 | B16: A009 | C16: Nettur et al. | D16: 2025 | E16: Cypress Copilot: Development of an AI Assistant for Boosting Productivity and Transforming Web Application Testing | F16: IEEE Access | G16: 10.1109/access.2024.3521407 | H16: Exclude | I16: Not assessed | J16: E1a | K16: Cypress/BDD test-code assistant aimed at QA productivity; no AI-TD, specification, or IS success.
A17: 16 | B17: A010 | C17: Krebs & Mazumdar | D17: 2025 | E17: Analyzing LLM-Generated Code According to Four ISO/IEC 5055:2021 Categories | F17: IEEE Access | G17: 10.1109/access.2025.3637569 | H17: Include | I17: Include | J17: INC | K17: Static analysis of LLM-generated code under the four ISO/IEC 5055 quality categories.
A18: 17 | B18: A011 | C18: Khalfaoui et al. | D18: 2025 | E18: Microservices-Driven Automation in Full-Stack Development: Bridging Efficiency and Innovation With FSMicroGenerator | F18: IEEE Access | G18: 10.1109/access.2025.3589285 | H18: Exclude | I18: Not assessed | J18: E1a | K18: Low-code full-stack generation from UML/templates without LLMs; technical debt mentioned only rhetorically.
A19: 18 | B19: A012 | C19: Wang | D19: 2026 | E19: CurricuForge: A Unified Framework for Progressive Code Generation Through Curriculum-Guided Multi-Agent Collaboration With Symbolic Verification | F19: IEEE Access | G19: 10.1109/access.2026.3668847 | H19: Exclude | I19: Not assessed | J19: E1b | K19: Curriculum-learning framework to train LLMs for code correctness on benchmarks; model optimization, no AI-TD.
... A27: 26 | B27: A020 | C27: Esirik & Gökalp | D27: 2026 | E27: A User-Centric Domain-Adaptive Quality Model for Benchmarking Generative AI Systems | F27: IEEE Access | G27: 10.1109/access.2026.3683220 | H27: Maybe | I27: Exclude | J27: FT-E | K27: AHP/Delphi quality model to benchmark GenAI systems as products; evaluates the AI system, not the generated code.
A28: 27 | C28: Alshahrani et al. | D28: 2025 | E28: Architectural Styles and Quality Attributes in AI-Based Video Software: A Systematic Literature Review | F28: IEEE Access | G28: 10.1109/access.2025.3625266 | H28: Exclude | I28: Not assessed | J28: E1c | K28: SLR of architectures and quality attributes in AI-based video software; unrelated domain.
A29: 28 | C29: Mehmood et al. | D29: 2024 | E29: Test Suite Optimization Using Machine Learning Techniques: A Comprehensive Study | F29: IEEE Access | G29: 10.1109/access.2024.3490453 | H29: Exclude | I29: Not assessed | J29: E1a | K29: Review of ML/GenAI techniques for test-suite optimization; no AI-TD.
A30: 29 | C30: Bagies | D30: 2026 | E30: Transformer-Based Classification of Security-Related Mobile App Reviews Using Active Learning | F30: IEEE Access | G30: 10.1109/access.2026.3692620 | H30: Exclude | I30: Not assessed | J30: E1c | K30: Transformer classification of security-related mobile-app reviews; NLP on user reviews.
A31: 30 | C31: Caldas et al. | D31: 2024 | E31: Runtime Verification and Field-Based Testing for ROS-Based Robotic Systems | F31: IEEE Transactions on Software Engineering | G31: 10.1109/tse.2024.3444697 | H31: Exclude | I31: Not assessed | J31: E1c | K31: Runtime verification and field testing for ROS-based robotic systems; unrelated domain.
A32: 31 | B32: A027 | C32: Zhuo et al. | D32: 2026 | E32: Getting Acquainted with Your LLMs: Are They Aware of Smelly Code? | F32: IEEE Software | G32: 10.1109/ms.2026.3665838 | H32: Include | I32: Include | J32: INC | K32: Empirical probe of LLM awareness of code smells; models rationalize smelly code.
A33: 32 | B33: A028 | C33: Lee & Joe | D33: 2025 | E33: A GPT-Based Code Review System With Accurate Feedback for Programming Education | F33: IEEE Access | G33: 10.1109/access.2025.3581139 | H33: Exclude | I33: Not assessed | J33: E1a | K33: GPT-4o code-review system for primary/secondary programming education; pre-university pedagogy, no AI-TD.
A34: 33 | B34: A029 | C34: Cheah et al. | D34: 2025 | E34: Descriptor: A Corpus of Synthesizable Verilog RTL Modules Dataset for EDA Research (CORE) | F34: IEEE Data Descriptions | G34: 10.1109/ieeedata.2025.3620273 | H34: Exclude | I34: Not assessed | J34: E1c | K34: Dataset of synthesizable Verilog RTL modules for EDA research; hardware description domain.
A35: 34 | B35: A030 | C35: Ginde et al. | D35: 2025 | E35: Rethinking Technological Investment and Cost-Benefit: A Software Requirements Dependency Extraction Case Study | F35: IEEE Access | G35: 10.1109/access.2025.3556313 | H35: Exclude | I35: Not assessed | J35: E1a | K35: ROI analysis of ML techniques for requirements-dependency extraction; no AI-TD.
A36: 35 | B36: A031 | C36: Xiang & Shao | D36: 2024 | E36: SumLLaMA: Efficient Contrastive Representations and Fine-Tuned Adapters for Bug Report Summarization | F36: IEEE Access | G36: 10.1109/access.2024.3397326 | H36: Exclude | I36: Not assessed | J36: E1a | K36: Fine-tuned LLM for bug-report summarization (ROUGE); NLP task, no AI-TD in generated code.
A37: 36 | B37: A032 | C37: Karnalim & Setiawan | D37: 2026 | E37: E-STRANGE: A programming support platform in academia for code ethics, quality, and efficiency | F37: Software Impacts | G37: 10.1016/j.simpa.2026.100814 | H37: Exclude | I37: Not assessed | J37: E1a | K37: Gamified platform assessing ethics, quality, and efficiency of student code; pedagogical tool, no AI-TD in IS projects.
A38: 37 | B38: A033 | C38: Gao et al. | D38: 2025 | E38: SVA-ICL: Improving LLM-based software vulnerability assessment via in-context learning and information fusion | F38: Information and Software Technology | G38: 10.1016/j.infsof.2025.107803 | H38: Exclude | I38: Not assessed | J38: E1c | K38: In-context learning for C/C++ vulnerability (CVE) assessment; security detection not tied to maintainability.
A39: 38 | B39: A034 | C39: Bishop et al. | D39: 2026 | E39: On-demand generation of high-quality software engineering datasets using large language models and ontologies | F39: Automated Software Engineering | G39: 10.1007/s10515-026-00617-w | H39: Exclude | I39: Not assessed | J39: E1a | K39: Synthetic SE dataset generation with LLMs for non-functional requirement classification; requirements data synthesis.
A40: 39 | B40: A035 | C40: Pezzè et al. | D40: 2025 | E40: A 2030 Roadmap for Software Engineering | F40: ACM Transactions on Software Engineering and Methodology | G40: 10.1145/3731559 | H40: Exclude | I40: Not assessed | J40: E1d | K40: Software engineering 2030 roadmap; too general to provide evidence on AI-TD.
A41: 40 | B41: A036 | C41: Al-Hashimi | D41: 2026 | E41: A generative AI cybersecurity risks mitigation model for code generation: using ANN-ISM hybrid approach | F41: Scientific Reports | G41: 10.1038/s41598-025-34350-3 | H41: Exclude | I41: Not assessed | J41: E1c | K41: ANN-ISM model of cybersecurity risks in GenAI code; security focus not tied to maintainability.
A42: 41 | B42: A037 | C42: Alomar | D42: 2025 | E42: Nurturing Code Quality: Leveraging Static Analysis and Large Language Models for Software Quality in Education | F42: ACM Transactions on Computing Education | G42: 10.1145/3722229 | H42: Include | I42: Include | J42: INC | K42: PMD + ChatGPT in university code review (155 submissions); added value of the LLM over the linter.
A43: 42 | B43: A038 | C43: Zhang et al. | D43: 2026 | E43: CITYWALK: Enhancing LLM-Based C++ Unit Test Generation via Project-Dependency Awareness and Language-Specific Knowledge | F43: ACM Transactions on Software Engineering and Methodology | G43: 10.1145/3763791 | H43: Exclude | I43: Not assessed | J43: E1a | K43: LLM framework for C++ unit-test generation; testing automation.
... A142: 141 | B142: A135 | C142: Lu et al. | D142: 2025 | E142: CodeTranFix: A Neural Machine Translation Approach for Context-Aware Java Program Repair with CodeBERT | F142: Applied Sciences (Switzerland) | G142: 10.3390/app15073632 | H142: Exclude | I142: Not assessed | J142: E1a | K142: NMT + CodeBERT program repair on Defects4J; repair metrics, no AI-TD in LLM code.

Sheet S4b_Screening_compl
A1: n | B1: search_string | C1: first_author | D1: year | E1: title | F1: venue | G1: doi | H1: ta_decision | I1: ft_decision | J1: reason_code | K1: rationale
A2: 1 | B2: B11 | C2: Newcomb et al. | D2: 2025 | E2: Preconditions and Postconditions as Design Constraints for LLM Code Generation | F2: IEEE Access | G2: 10.1109/access.2025.3625819 | H2: Include | I2: Include | J2: INC | K2: Design-by-contract pre- and postconditions as structured specification before LLM generation; pass@k across six LLMs.
A3: 2 | B3: B11 | C3: Khaldi et al. | D3: 2026 | E3: Agentic-AI Framework for Integrated Design, Implementation, Testing, and Operation of Digital Twin Networks | F3: IEEE Open Journal of the Communications Society | G3: 10.1109/ojcoms.2026.3686199 | H3: Exclude | I3: Not assessed | J3: E1c | K3: Agentic-AI framework for 6G digital-twin networks; network KPIs, not code quality.
A4: 3 | B4: B12 | C4: Moskalenko | D4: 2026 | E4: DEVELOPMENT AND VERIFICATION OF AN ORCHESTRATION ARCHITECTURE OF AI AGENTS FOR AUTOMATED API TESTING WITH A UNIFIED REPRESENTATION OF REQUIREMENTS | F4: Technology Audit and Production Reserves | G4: 10.15587/2706-5448.2026.360928 | H4: Maybe | I4: Exclude | J4: FT-E | K4: Orchestration architecture for automated API testing; at full text the object is test generation, with no code-quality or debt measure.
A5: 4 | B5: B12 | C5: Hassani et al. | D5: 2026 | E5: From law to Gherkin: A human-centred quasi-experiment on the quality of LLM-generated behavioral specifications from food-safety regulations | F5: Information and Software Technology | G5: 10.1016/j.infsof.2026.108122 | H5: Exclude | I5: Not assessed | J5: E1a | K5: Generates BDD (Gherkin) specifications from legal texts; no code.
A6: 5 | B6: B12 | C6: Li & Zheng | D6: 2025 | E6: Enhancing Requirements via Structured Formalization and Process-State Consistency Validation: An LLM-Assisted Test-Driven Framework | F6: IET Software | G6: 10.1049/sfw2/6714956 | H6: Exclude | I6: Not assessed | J6: E1a | K6: Structured formalization of use-case specifications and tests; the object is specifications and tests, not code.
